Workbook

Sheet Stock Selection
A1: 1. BRAC Bank
A2: Year | B2: P/E | C2: NAV | D2: ROA | E2: ROE | F2: NPM | G2: EPS
A3: 2021 | B3: 14.09 | C3: 30.24 | D3: 0.0131 | E3: 0.1038 | F3: 0.1901 | G3: 2.39
A4: 2022 | B4: 9.55 | C4: 32.37 | D4: 0.0102 | E4: 0.0777 | F4: 0.168 | G4: 2.63
A5: 2023 | B5: 7.57 | C5: 35.5 | D5: 0.0111 | E5: 0.1192 | F5: 0.1741 | G5: 3.32
A6: 2024 | B6: 7.05 | C6: 42.09 | D6: 0.0146 | E6: 0.1743 | F6: 0.2027 | G6: 5.37
A7: 2025 | B7: 6.92 | C7: 55.4 | D7: 0.0152 | E7: 0.2006 | F7: 0.2311 | G7: 7.93
A9: 2. NCC Bank
A10: Year | B10: P/E | C10: NAV | D10: ROA | E10: ROE | F10: NPM | G10: EPS
A11: 2021 | B11: 5.95 | C11: 21.11 | D11: 0.95% | E11: 11.72% | F11: 22% | G11: 2.37
A12: 2022 | B12: 5.52 | C12: 20.86 | D12: 0.87% | E12: 11.41% | F12: 20.7% | G12: 2.38
A13: 2023 | B13: 6.33 | C13: 21.82 | D13: 0.72% | E13: 9.48% | F13: 16% | G13: 2.07
A14: 2024 | B14: 2.74 | C14: 22.37 | D14: 1.26% | E14: 16.2% | F14: 26.1% | G14: 2.1
A15: 2025 | B15: 2.84 | C15: 27.2 | D15: 1.19% | E15: 15.78% | F15: 25.4% | G15: 4.29
A17: 3. IPDC
A18: Year | B18: P/E | C18: NAV | D18: ROA | E18: ROE | F18: NPM | G18: EPS
A19: 2021 | B19: 16.26 | C19: 14.79 | D19: 0.0104 | E19: 0.1387 | F19: 0.257 | G19: 2.05
A20: 2022 | B20: 23.72 | C20: 15.84 | D20: 0.0104 | E20: 0.1324 | F20: 0.29 | G20: 2.1
A21: 2023 | B21: 62.33 | C21: 15.72 | D21: 0.0037 | E21: 0.0508 | F21: 0.12 | G21: 0.8
A22: 2024 | B22: 19.63 | C22: 16.08 | D22: 0.0041 | E22: 0.0526 | F22: 0.113 | G22: 0.85
A23: 2025 | B23: 16.98 | C23: 17 | D23: 0.0046 | E23: 0.0624 | F23: 0.132 | G23: 1.06
A25: 4. DBH Finance PLC. (DBH)
A26: Year | B26: P/E | C26: NAV | D26: ROA | E26: ROE | F26: NPM | G26: EPS
A27: 2021 | B27: 13.09 | C27: 35.71 | D27: 0.0173 | E27: 0.1441 | F27: 0.421 | G27: 5.15
A28: 2022 | B28: 11.09 | C28: 39.37 | D28: 0.0165 | E28: 0.1274 | F28: 0.477 | G28: 5.01
A29: 2023 | B29: 11.46 | C29: 42.78 | D29: 0.0146 | E29: 0.1134 | F29: 0.454 | G29: 4.85
A30: 2024 | B30: 7.67 | C30: 46.33 | D30: 0.015 | E30: 0.1074 | F30: 0.398 | G30: 4.97
A31: 2025 | B31: 7.38 | C31: 49.55 | D31: 0.0138 | E31: 0.0947 | F31: 0.381 | G31: 4.69
A33: 5. Paramount
A34: Year | B34: P/E | C34: NAV | D34: ROA | E34: ROE | F34: NPM | G34: EPS
A35: 2021 | B35: 24.22 | C35: 25.26 | D35: 0.0783 | E35: 0.1198 | F35: 0.3217 | G35: 3.03
A36: 2022 | B36: 23.8 | C36: 25.82 | D36: 0.0463 | E36: 0.0724 | F36: 0.2228 | G36: 1.87
A37: 2023 | B37: 32.77 | C37: 26.56 | D37: 0.0415 | E37: 0.0653 | F37: 0.2014 | G37: 1.73
A38: 2024 | B38: 18.5 | C38: 27.25 | D38: 0.0498 | E38: 0.0817 | F38: 0.2041 | G38: 2.23
A39: 2025 | B39: 19.65 | C39: 28.16 | D39: 0.0497 | E39: 0.0779 | F39: 0.2029 | G39: 2.19
A41: 6. Asia Pecific General Insurance PLC
A42: Year | B42: P/E | C42: NAV | D42: ROA | E42: ROE | F42: NPM | G42: EPS
A43: 2021 | B43: 29.39 | C43: 21.96 | D43: 0.0694 | E43: 0.1061 | F43: 0.2501 | G43: 2.33
A44: 2022 | B44: 17.59 | C44: 22.53 | D44: 0.068 | E44: 0.105 | F44: 0.2274 | G44: 2.37
A45: 2023 | B45: 24.23 | C45: 23.1 | D45: 0.0564 | E45: 0.0895 | F45: 0.17 | G45: 2.07
...

Sheet Price Data
C1: Bank | E1: Financial Institutions | G1: Insurance | I1: Food & Allied | L1: Miscellaneous | M1: Tannery | N1: Cement | O1: Telecommunication | P1: Pharmacuticals & Chemicals | T1: Engineering | U1: IT Sector | V1: Fuel & Power
A2: Years | B2: Months | C2: BRACBANK | D2: NCC | E2: IPDC | F2: DBH | G2: PARAMOUNT | H2: ASIAPACINS | I2: LOVELLO | J2: FINEFOODS | K2: OLYMPIC | L2: INDEXAGRO | M2: APEXFOOT | N2: CONFIDCEM | O2: GP | P2: IBNSINA | Q2: RENATA | R2: MARICO | S2: RECKITTBEN | T2: KDSALTD | U2: ADNTEL | V2: JAMUNAOIL
A3: 2021 | B3: August | C3: 30.79 | D3: 15.6 | E3: 36.86 | F3: 74.73 | G3: 89.2 | H3: 71 | I3: 31.27 | J3: 56.5 | K3: 174.2 | L3: 129.7 | M3: 132.69 | N3: 141.14 | O3: 362.6 | P3: 256.5 | Q3: 1202.46 | R3: 2322.8 | S3: 4475.1 | T3: 58 | U3: 61.3 | V3: 182.9
B4: September | C4: 31.11 | D4: 15.7 | E4: 46.29 | F4: 78.45 | G4: 83.5 | H4: 68.7 | I4: 33.09 | J4: 53.7 | K4: 196.8 | L4: 118.4 | M4: 174.13 | N4: 152.57 | O4: 380.2 | P4: 273.1 | Q4: 1217.08 | R4: 2333.7 | S4: 4837.2 | T4: 76 | U4: 74.1 | V4: 183.9
B5: October | C5: 29.94 | D5: 15.5 | E5: 39.52 | F5: 72.91 | G5: 78.5 | H5: 67.8 | I5: 32.36 | J5: 41.3 | K5: 174.8 | L5: 105.3 | M5: 156.03 | N5: 123.81 | O5: 358.5 | P5: 269.1 | Q5: 1230.76 | R5: 2295.1 | S5: 5038.7 | T5: 73.1 | U5: 58.6 | V5: 173.4
B6: November | C6: 35.43 | D6: 15.4 | E6: 37.24 | F6: 70.18 | G6: 71 | H6: 61.3 | I6: 33.45 | J6: 38 | K6: 159 | L6: 111.1 | M6: 139.92 | N6: 108.29 | O6: 348.3 | P6: 268.5 | Q6: 1206.07 | R6: 2280.5 | S6: 4892.4 | T6: 63.4 | U6: 55.9 | V6: 171
B7: December | C7: 36.15 | D7: 15.3 | E7: 36.76 | F7: 70.09 | G7: 73.3 | H7: 68.5 | I7: 30.55 | J7: 50.4 | K7: 160.6 | L7: 122.2 | M7: 161.14 | N7: 116.1 | O7: 349.5 | P7: 271.3 | Q7: 1226.17 | R7: 2301 | S7: 5729.9 | T7: 70 | U7: 52.4 | V7: 171.1
A8: 2022 | B8: January | C8: 36.08 | D8: 15.2 | E8: 37.33 | F8: 69.82 | G8: 71.2 | H8: 64.8 | I8: 35.18 | J8: 46.8 | K8: 161.7 | L8: 116.7 | M8: 196.42 | N8: 115.33 | O8: 355.9 | P8: 283 | Q8: 1245.14 | R8: 2356.1 | S8: 5840.1 | T8: 56.9 | U8: 51.8 | V8: 167.8
B9: February | C9: 35.3 | D9: 15 | E9: 34.67 | F9: 66.64 | G9: 67 | H9: 56.9 | I9: 33.27 | J9: 47.9 | K9: 147.2 | L9: 106.6 | M9: 185.73 | N9: 111.33 | O9: 340 | P9: 285 | Q9: 1271.4 | R9: 2399.4 | S9: 5853.3 | T9: 55 | U9: 60.8 | V9: 168.2
B10: March | C10: 32.49 | D10: 15.4 | E10: 39.33 | F10: 65.6 | G10: 61.4 | H10: 55.2 | I10: 37.91 | J10: 45.6 | K10: 137.2 | L10: 102.8 | M10: 183.26 | N10: 108.57 | O10: 328.9 | P10: 298.1 | Q10: 1264.77 | R10: 2355.2 | S10: 5388.4 | T10: 56.9 | U10: 65.1 | V10: 163.2
B11: April | C11: 32.32 | D11: 15.6 | E11: 54.19 | F11: 66.4 | G11: 57.1 | H11: 57.5 | I11: 38.36 | J11: 41.8 | K11: 130.7 | L11: 105.1 | M11: 176.83 | N11: 108.29 | O11: 319.9 | P11: 295.7 | Q11: 1272.9 | R11: 2353.1 | S11: 4871.3 | T11: 54.6 | U11: 68.3 | V11: 167.6
B12: May | C12: 28.88 | D12: 15.6 | E12: 50.1 | F12: 62.2 | G12: 48.3 | H12: 51.9 | I12: 38.36 | J12: 42.2 | K12: 124 | L12: 100.1 | M12: 165.23 | N12: 98.76 | O12: 307.1 | P12: 288.3 | Q12: 1247.76 | R12: 2344.8 | S12: 4695.9 | T12: 55.1 | U12: 65.7 | V12: 167.6
B13: June | C13: 29.16 | D13: 14.4 | E13: 50.19 | F13: 62.1 | G13: 51.8 | H13: 51.3 | I13: 38.09 | J13: 45.2 | K13: 124.1 | L13: 102.1 | M13: 163.19 | N13: 98.48 | O13: 294.1 | P13: 296.7 | Q13: 1257.57 | R13: 2421 | S13: 4868.5 | T13: 60 | U13: 65.8 | V13: 177.2
B14: July | C14: 27.12 | D14: 13.8 | E14: 54.95 | F14: 59 | G14: 50.4 | H14: 47.8 | I14: 34.64 | J14: 44.3 | K14: 120.3 | L14: 103.8 | M14: 158.2 | N14: 90.1 | O14: 294.3 | P14: 287.5 | Q14: 1218.41 | R14: 2449.7 | S14: 4796.1 | T14: 80.6 | U14: 60 | V14: 168.9
B15: August | C15: 27.12 | D15: 14.1 | E15: 65.14 | F15: 62.6 | G15: 48.6 | H15: 49.7 | I15: 37.82 | J15: 52.8 | K15: 137 | L15: 108.6 | M15: 174.06 | N15: 102.29 | O15: 287.8 | P15: 301 | Q15: 1224.39 | R15: 2472.6 | S15: 4892.2 | T15: 83 | U15: 63.1 | V15: 170.2
B16: September | C16: 27.05 | D16: 13.8 | E16: 63.33 | F16: 57.8 | G16: 46.5 | H16: 46.1 | I16: 38.55 | J16: 59.6 | K16: 129.6 | L16: 141.5 | M16: 182.78 | N16: 94 | O16: 286.6 | P16: 306.4 | Q16: 1217.94 | R16: 2430.7 | S16: 4830.9 | T16: 77 | U16: 84.8 | V16: 167.4
B17: October | C17: 27.05 | D17: 13.8 | E17: 54.86 | F17: 57.8 | G17: 46.5 | H17: 44.4 | I17: 36.18 | J17: 62.5 | K17: 113.7 | L17: 107.7 | M17: 170.25 | N17: 89.05 | O17: 286.6 | P17: 286.6 | Q17: 1217.94 | R17: 2421.5 | S17: 4760.7 | T17: 93.4 | U17: 131 | V17: 167.5
B18: November | C18: 27.05 | D18: 13.8 | E18: 54.86 | F18: 57.8 | G18: 46.5 | H18: 43.6 | I18: 34.45 | J18: 58.2 | K18: 120.2 | L18: 103.8 | M18: 170.25 | N18: 89.05 | O18: 286.6 | P18: 286.6 | Q18: 1217.9 | R18: 2421.5 | S18: 4760.7 | T18: 77 | U18: 101.4 | V18: 169
B19: December | C19: 27.05 | D19: 13.8 | E19: 54.86 | F19: 57.8 | G19: 44.5 | H19: 41.6 | I19: 34.45 | J19: 59.7 | K19: 124 | L19: 103.6 | M19: 173.29 | N19: 89 | O19: 286.6 | P19: 286.6 | Q19: 1217.9 | R19: 2421.5 | S19: 4760.7 | T19: 77 | U19: 114.1 | V19: 167.3
A20: 2023 | B20: January | C20: 27.05 | D20: 13.8 | E20: 54.86 | F20: 57.8 | G20: 43.5 | H20: 47.9 | I20: 34.45 | J20: 57.7 | K20: 138 | L20: 103.6 | M20: 170.25 | N20: 89 | O20: 286.6 | P20: 286.6 | Q20: 1217.9 | R20: 2421.5 | S20: 4760.7 | T20: 77 | U20: 115 | V20: 170
B21: February | C21: 27.05 | D21: 13.8 | E21: 54.86 | F21: 57.8 | G21: 38.4 | H21: 43.9 | I21: 34.45 | J21: 61.5 | K21: 148.7 | L21: 103.6 | M21: 195.31 | N21: 89 | O21: 286.6 | P21: 286.6 | Q21: 1217.9 | R21: 2421.5 | S21: 4760.7 | T21: 77 | U21: 130.7 | V21: 170
B22: March | C22: 27.05 | D22: 13.8 | E22: 54.86 | F22: 57.8 | G22: 38.4 | H22: 43.6 | I22: 34.45 | J22: 72.2 | K22: 155.4 | L22: 103.6 | M22: 198.21 | N22: 89 | O22: 286.6 | P22: 286.6 | Q22: 1217.9 | R22: 2421.5 | S22: 4760.7 | T22: 77 | U22: 163.6 | V22: 178.5
B23: April | C23: 27.05 | D23: 13.8 | E23: 54.86 | F23: 56.7 | G23: 38.4 | H23: 44.8 | I23: 34.45 | J23: 71.4 | K23: 165.9 | L23: 103.6 | M23: 223.34 | N23: 89 | O23: 286.6 | P23: 286.6 | Q23: 1217.9 | R23: 2421.5 | S23: 4777.9 | T23: 77 | U23: 131.5 | V23: 182.9
B24: May | C24: 25.16 | D24: 13.8 | E24: 54.86 | F24: 56.7 | G24: 57.9 | H24: 54.9 | I24: 34.45 | J24: 92.8 | K24: 155.3 | L24: 103.6 | M24: 209.59 | N24: 89 | O24: 286.6 | P24: 286.6 | Q24: 1217.9 | R24: 2421.5 | S24: 4772.2 | T24: 77 | U24: 133.7 | V24: 180.9
B25: June | C25: 25.16 | D25: 13.1 | E25: 54.86 | F25: 56.7 | G25: 48.3 | H25: 48.8 | I25: 34.45 | J25: 117.7 | K25: 153.6 | L25: 103.6 | M25: 207.87 | N25: 89 | O25: 286.6 | P25: 286.6 | Q25: 1217.9 | R25: 2421.5 | S25: 4873.7 | T25: 77 | U25: 131.7 | V25: 179.9
B26: July | C26: 25.16 | D26: 13.1 | E26: 54.86 | F26: 56.7 | G26: 44.3 | H26: 61.9 | I26: 34.45 | J26: 123.6 | K26: 145.2 | L26: 103.6 | M26: 191.34 | N26: 89 | O26: 286.6 | P26: 286.6 | Q26: 1217.9 | R26: 2421.5 | S26: 4790 | T26: 77 | U26: 134.3 | V26: 177.5
B27: August | C27: 25.16 | D27: 13.1 | E27: 54.86 | F27: 56.7 | G27: 41.6 | H27: 56.8 | I27: 34.45 | J27: 122.9 | K27: 148.2 | L27: 103.6 | M27: 188.1 | N27: 89 | O27: 286.6 | P27: 286.6 | Q27: 1217.9 | R27: 2560.2 | S27: 4824.1 | T27: 77 | U27: 131.2 | V27: 176.5
B28: September | C28: 25.16 | D28: 13.1 | E28: 54.86 | F28: 56.7 | G28: 71.1 | H28: 61.4 | I28: 34.45 | J28: 118 | K28: 153.1 | L28: 103.6 | M28: 203.57 | N28: 89 | O28: 286.6 | P28: 286.6 | Q28: 1217.9 | R28: 2471.9 | S28: 4763.4 | T28: 77 | U28: 123.9 | V28: 177.1
B29: October | C29: 25.16 | D29: 13.1 | E29: 54.86 | F29: 56.7 | G29: 58.6 | H29: 53 | I29: 34.45 | J29: 127.1 | K29: 152.9 | L29: 103.6 | M29: 191.93 | N29: 89 | O29: 286.6 | P29: 286.6 | Q29: 1217.9 | R29: 2469.1 | S29: 4760.7 | T29: 77 | U29: 119.1 | V29: 177.7
B30: November | C30: 25.16 | D30: 13.1 | E30: 54.86 | F30: 56.7 | G30: 53.5 | H30: 50.7 | I30: 34.45 | J30: 122.8 | K30: 143.2 | L30: 103.6 | M30: 187.27 | N30: 89 | O30: 286.6 | P30: 286.6 | Q30: 1217.9 | R30: 2421.5 | S30: 4760.7 | T30: 77 | U30: 109.5 | V30: 177.8
B31: December | C31: 25.16 | D31: 13.1 | E31: 54.86 | F31: 56.7 | G31: 56.8 | H31: 50.1 | I31: 34.45 | J31: 133.9 | K31: 152 | L31: 103.6 | M31: 187.27 | N31: 89 | O31: 286.6 | P31: 286.6 | Q31: 1217.9 | R31: 2460.7 | S31: 4760.7 | T31: 77 | U31: 117.1 | V31: 168.5
A32: 2024 | B32: January | C32: 26.49 | D32: 11.7 | E32: 29.9 | F32: 49.1 | G32: 58.5 | H32: 51.1 | I32: 29.73 | J32: 133.1 | K32: 152.7 | L32: 77.4 | M32: 173.38 | N32: 74.4 | O32: 286.6 | P32: 266.7 | Q32: 1217.9 | R32: 2520.4 | S32: 4988 | T32: 59.3 | U32: 127.9 | V32: 169.9
B33: February | C33: 30 | D33: 11.9 | E33: 30.67 | F33: 47 | G33: 54.6 | H33: 50.1 | I33: 43.64 | J33: 159.1 | K33: 145.2 | L33: 81.1 | M33: 183.49 | N33: 80.4 | O33: 286.6 | P33: 271 | Q33: 943.6 | R33: 2515.9 | S33: 5007.7 | T33: 55.1 | U33: 124.1 | V33: 174.5
B34: March | C34: 28.25 | D34: 11.9 | E34: 26 | F34: 40.8 | G34: 54.6 | H34: 45.1 | I34: 49.64 | J34: 178 | K34: 152.1 | L34: 71.9 | M34: 177.09 | N34: 73.7 | O34: 237.8 | P34: 263.2 | Q34: 776 | R34: 2444.9 | S34: 4687.9 | T34: 45 | U34: 119.3 | V34: 173.3
B35: April | C35: 27.19 | D35: 11.9 | E35: 20.76 | F35: 37.1 | G35: 58.1 | H35: 43.2 | I35: 72.45 | J35: 177.8 | K35: 144.1 | L35: 66.6 | M35: 170.4 | N35: 75 | O35: 235.8 | P35: 256.6 | Q35: 768.7 | R35: 2328.5 | S35: 4474.9 | T35: 45.2 | U35: 110 | V35: 174.5
B36: May | C36: 26.05 | D36: 12.3 | E36: 18.76 | F36: 32.6 | G36: 54.6 | H36: 39.3 | I36: 79 | J36: 165.8 | K36: 131.8 | L36: 62.9 | M36: 155.93 | N36: 65.1 | O36: 223.5 | P36: 243 | Q36: 634.2 | R36: 2007.3 | S36: 4122.9 | T36: 40 | U36: 86.3 | V36: 170.1
B37: June | C37: 26.51 | D37: 9.8 | E37: 17.71 | F37: 31.7 | G37: 53.3 | H37: 39.9 | I37: 78.73 | J37: 165.1 | K37: 132.4 | L37: 64.3 | M37: 173.75 | N37: 67.8 | O37: 247.7 | P37: 249.8 | Q37: 770.1 | R37: 2274.5 | S37: 4600 | T37: 37.9 | U37: 99.1 | V37: 174.6
B38: July | C38: 28.68 | D38: 10.4 | E38: 19.05 | F38: 31.7 | G38: 56.2 | H38: 38.4 | I38: 85.18 | J38: 163 | K38: 119.5 | L38: 62.6 | M38: 165.82 | N38: 62.5 | O38: 252.5 | P38: 242.7 | Q38: 710.1 | R38: 2292 | S38: 4767.7 | T38: 38 | U38: 92.4 | V38: 178.5
B39: August | C39: 41.43 | D39: 12.4 | E39: 23.62 | F39: 43.3 | G39: 48.3 | H39: 39 | I39: 69.73 | J39: 160.5 | K39: 201.1 | L39: 71.1 | M39: 172.58 | N39: 76.3 | O39: 344 | P39: 322.5 | Q39: 761.1 | R39: 2263.7 | S39: 4839.4 | T39: 41.6 | U39: 91.1 | V39: 194.3
B40: September | C40: 41.89 | D40: 10.8 | E40: 20.1 | F40: 38.5 | G40: 38.5 | H40: 36.3 | I40: 78.91 | J40: 164 | K40: 184.5 | L40: 66.1 | M40: 174.47 | N40: 59.1 | O40: 350.2 | P40: 357.9 | Q40: 700.6 | R40: 2311.9 | S40: 4782.5 | T40: 34.9 | U40: 93.9 | V40: 178.9
...

Sheet Cash Dividend
C1: Bank | E1: Financial Institutions | G1: Insurance | I1: Food & Allied | L1: Miscellaneous | M1: Tannery | N1: Cement | O1: Telecommunication | P1: Pharmacuticals & Chemicals | T1: Engineering | U1: IT Sector | V1: Fuel & Power
A2: Years | B2: Months | C2: BRACBANK | D2: NCC | E2: IPDC | F2: DBH | G2: PARAMOUNT | H2: ASIAPACINS | I2: LOVELLO | J2: FINEFOODS | K2: OLYMPIC | L2: INDEXAGRO | M2: APEXFOOT | N2: CONFIDCEM | O2: GP | P2: IBNSINA | Q2: RENATA | R2: MARICO | S2: RECKITTBEN | T2: KDSALTD | U2: ADNTEL | V2: JAMUNAOIL
A3: 2021 | B3: August
B4: September
B5: October | L5: =10*25% -> 2.5 | M5: 3.5 | P5: 4.7
B6: November | I6: =10*11% -> 1.1 | K6: 5.4 | N6: 2.5 | Q6: 14.5 | T6: 1.5 | U6: 1
B7: December
A8: 2022 | B8: January | V8: 12
B9: February | O9: 25
B10: March | E10: =10*12% -> 1.2 | F10: =10*15% -> 1.5
B11: April | C11: 0.75 | G11: =10*10% -> 1 | S11: =10*1650% -> 165
B12: May | H12: =10*18% -> 1.8 | R12: =10*800% -> 80
B13: June | D13: =10*12% -> 1.2
B14: July
B15: August
B16: September | P16: 6
B17: October | M17: 3.5 | U17: 1
B18: November | I18: =10*12% -> 1.2 | J18: 0.15 | K18: 4.5 | L18: 1 | Q18: 14 | T18: 1.6
B19: December | N19: 0.5 | V19: 12
A20: 2023 | B20: January
B21: February | O21: 22
B22: March | E22: =10*10% -> 1 | S22: 98
B23: April | F23: =10*15% -> 1.5
B24: May | C24: 0.75 | G24: =10*10% -> 1 | H24: =10*15% -> 1.5 | R24: 75
B25: June | D25: =10*5% -> 0.5
B26: July
B27: August
B28: September | P28: 6
B29: October | M29: 3.5 | U29: 1.5
B30: November | I30: =10*10% -> 1 | J30: 0.125 | K30: 6 | L30: 2 | Q30: 6.25 | T30: 1
B31: December | N31: 0.5 | V31: 13
A32: 2024 | B32: January
B33: February | O33: 12.5
B34: March
B35: April | E35: =10*5% -> 0.5 | F35: =10*15% -> 1.5 | S35: 55
B36: May | C36: 1 | G36: =10*10% -> 1 | H36: =10*12% -> 1.2 | R36: 20
B37: June | D37: =10*12% -> 1.2
B38: July
B39: August
B40: September | N40: 1
...

Sheet Stock Dividend
C1: Bank | E1: Financial Institutions | G1: Insurance | I1: Food & Allied | L1: Miscellaneous | M1: Tannery | N1: Cement | O1: Telecommunication | P1: Pharmacuticals & Chemicals | T1: Engineering | U1: IT Sector | V1: Fuel & Power
A2: Years | B2: Months | C2: BRACBANK | D2: NCC | E2: IPDC | F2: DBH | G2: PARAMOUNT | H2: ASIAPACINS | I2: LOVELLO | J2: FINEFOODS | K2: OLYMPIC | L2: INDEXAGRO | M2: APEXFOOT | N2: CONFIDCEM | O2: GP | P2: IBNSINA | Q2: RENATA | R2: MARICO | S2: RECKITTBEN | T2: KDSALTD | U2: ADNTEL | V2: JAMUNAOIL
A3: 2021 | B3: August
B4: September
B5: October | M5: 0.05
B6: November | Q6: 0.1
B7: December
A8: 2022 | B8: January
B9: February
B10: March | F10: 0.1
B11: April | C11: 0.075
B12: May
B13: June | D13: 0.04
B14: July
B15: August
B16: September
B17: October | M17: 0.1
B18: November | Q18: 0.07
B19: December | N19: 0.05
A20: 2023 | B20: January
B21: February
B22: March
B23: April | F23: 0.02
B24: May | C24: 0.075
B25: June | D25: 0.05
B26: July
B27: August
B28: September
B29: October | M29: 0.1
B30: November
B31: December | N31: 0.05
A32: 2024 | B32: January
B33: February
B34: March
B35: April | E35: 0.05
B36: May | C36: 0.1
B37: June
B38: July
B39: August
B40: September
...

Sheet Right Share Ratio
C1: Bank | E1: Financial Institutions | G1: Insurance | I1: Food & Allied | L1: Miscellaneous | M1: Tannery | N1: Cement | O1: Telecommunication | P1: Pharmacuticals & Chemicals | T1: Engineering | U1: IT Sector | V1: Fuel & Power
A2: Years | B2: Months | C2: BRACBANK | D2: NCC | E2: IPDC | F2: DBH | G2: PARAMOUNT | H2: ASIAPACINS | I2: LOVELLO | J2: FINEFOODS | K2: OLYMPIC | L2: INDEXAGRO | M2: APEXFOOT | N2: CONFIDCEM | O2: GP | P2: IBNSINA | Q2: RENATA | R2: MARICO | S2: RECKITTBEN | T2: KDSALTD | U2: ADNTEL | V2: JAMUNAOIL
A3: 2021 | B3: August
B4: September
B5: October
B6: November
B7: December
A8: 2022 | B8: January
B9: February
B10: March
B11: April
B12: May
B13: June
B14: July
B15: August
B16: September
B17: October
B18: November
B19: December
A20: 2023 | B20: January
B21: February
B22: March
B23: April
B24: May
B25: June
B26: July
B27: August
B28: September
B29: October
B30: November
B31: December
A32: 2024 | B32: January
B33: February
B34: March
B35: April
B36: May
B37: June
B38: July
B39: August
B40: September
...

Sheet Right Share Offer Price
C1: Bank | E1: Financial Institutions | G1: Insurance | I1: Food & Allied | L1: Miscellaneous | M1: Tannery | N1: Cement | O1: Telecommunication | P1: Pharmacuticals & Chemicals | T1: Engineering | U1: IT Sector | V1: Fuel & Power
A2: Years | B2: Months | C2: BRACBANK | D2: NCC | E2: IPDC | F2: DBH | G2: PARAMOUNT | H2: ASIAPACINS | I2: LOVELLO | J2: FINEFOODS | K2: OLYMPIC | L2: INDEXAGRO | M2: APEXFOOT | N2: CONFIDCEM | O2: GP | P2: IBNSINA | Q2: RENATA | R2: MARICO | S2: RECKITTBEN | T2: KDSALTD | U2: ADNTEL | V2: JAMUNAOIL
A3: 2021 | B3: August
B4: September
B5: October
B6: November
B7: December
A8: 2022 | B8: January
B9: February
B10: March
B11: April
B12: May
B13: June
B14: July
B15: August
B16: September
B17: October
B18: November
B19: December
A20: 2023 | B20: January
B21: February
B22: March
B23: April
B24: May
B25: June
B26: July
B27: August
B28: September
B29: October
B30: November
B31: December
A32: 2024 | B32: January
B33: February
B34: March
B35: April
B36: May
B37: June
B38: July
B39: August
B40: September
...

Sheet Split
C1: Bank | E1: Financial Institutions | G1: Insurance | I1: Food & Allied | L1: Miscellaneous | M1: Tannery | N1: Cement | O1: Telecommunication | P1: Pharmacuticals & Chemicals | T1: Engineering | U1: IT Sector | V1: Fuel & Power
A2: Years | B2: Months | C2: BRACBANK | D2: NCC | E2: IPDC | F2: DBH | G2: PARAMOUNT | H2: ASIAPACINS | I2: LOVELLO | J2: FINEFOODS | K2: OLYMPIC | L2: INDEXAGRO | M2: APEXFOOT | N2: CONFIDCEM | O2: GP | P2: IBNSINA | Q2: RENATA | R2: MARICO | S2: RECKITTBEN | T2: KDSALTD | U2: ADNTEL | V2: JAMUNAOIL
A3: 2021 | B3: August | C3: 1 | D3: 1 | E3: 1 | F3: 1 | G3: 1 | H3: 1 | I3: 1 | J3: 1 | K3: 1 | L3: 1 | M3: 1 | N3: 1 | O3: 1 | P3: 1 | Q3: 1 | R3: 1 | S3: 1 | T3: 1 | U3: 1 | V3: 1
B4: September | C4: 1 | D4: 1 | E4: 1 | F4: 1 | G4: 1 | H4: 1 | I4: 1 | J4: 1 | K4: 1 | L4: 1 | M4: 1 | N4: 1 | O4: 1 | P4: 1 | Q4: 1 | R4: 1 | S4: 1 | T4: 1 | U4: 1 | V4: 1
B5: October | C5: 1 | D5: 1 | E5: 1 | F5: 1 | G5: 1 | H5: 1 | I5: 1 | J5: 1 | K5: 1 | L5: 1 | M5: 1 | N5: 1 | O5: 1 | P5: 1 | Q5: 1 | R5: 1 | S5: 1 | T5: 1 | U5: 1 | V5: 1
B6: November | C6: 1 | D6: 1 | E6: 1 | F6: 1 | G6: 1 | H6: 1 | I6: 1 | J6: 1 | K6: 1 | L6: 1 | M6: 1 | N6: 1 | O6: 1 | P6: 1 | Q6: 1 | R6: 1 | S6: 1 | T6: 1 | U6: 1 | V6: 1
B7: December | C7: 1 | D7: 1 | E7: 1 | F7: 1 | G7: 1 | H7: 1 | I7: 1 | J7: 1 | K7: 1 | L7: 1 | M7: 1 | N7: 1 | O7: 1 | P7: 1 | Q7: 1 | R7: 1 | S7: 1 | T7: 1 | U7: 1 | V7: 1
A8: 2022 | B8: January | C8: 1 | D8: 1 | E8: 1 | F8: 1 | G8: 1 | H8: 1 | I8: 1 | J8: 1 | K8: 1 | L8: 1 | M8: 1 | N8: 1 | O8: 1 | P8: 1 | Q8: 1 | R8: 1 | S8: 1 | T8: 1 | U8: 1 | V8: 1
B9: February | C9: 1 | D9: 1 | E9: 1 | F9: 1 | G9: 1 | H9: 1 | I9: 1 | J9: 1 | K9: 1 | L9: 1 | M9: 1 | N9: 1 | O9: 1 | P9: 1 | Q9: 1 | R9: 1 | S9: 1 | T9: 1 | U9: 1 | V9: 1
B10: March | C10: 1 | D10: 1 | E10: 1 | F10: 1 | G10: 1 | H10: 1 | I10: 1 | J10: 1 | K10: 1 | L10: 1 | M10: 1 | N10: 1 | O10: 1 | P10: 1 | Q10: 1 | R10: 1 | S10: 1 | T10: 1 | U10: 1 | V10: 1
B11: April | C11: 1 | D11: 1 | E11: 1 | F11: 1 | G11: 1 | H11: 1 | I11: 1 | J11: 1 | K11: 1 | L11: 1 | M11: 1 | N11: 1 | O11: 1 | P11: 1 | Q11: 1 | R11: 1 | S11: 1 | T11: 1 | U11: 1 | V11: 1
B12: May | C12: 1 | D12: 1 | E12: 1 | F12: 1 | G12: 1 | H12: 1 | I12: 1 | J12: 1 | K12: 1 | L12: 1 | M12: 1 | N12: 1 | O12: 1 | P12: 1 | Q12: 1 | R12: 1 | S12: 1 | T12: 1 | U12: 1 | V12: 1
B13: June | C13: 1 | D13: 1 | E13: 1 | F13: 1 | G13: 1 | H13: 1 | I13: 1 | J13: 1 | K13: 1 | L13: 1 | M13: 1 | N13: 1 | O13: 1 | P13: 1 | Q13: 1 | R13: 1 | S13: 1 | T13: 1 | U13: 1 | V13: 1
B14: July | C14: 1 | D14: 1 | E14: 1 | F14: 1 | G14: 1 | H14: 1 | I14: 1 | J14: 1 | K14: 1 | L14: 1 | M14: 1 | N14: 1 | O14: 1 | P14: 1 | Q14: 1 | R14: 1 | S14: 1 | T14: 1 | U14: 1 | V14: 1
B15: August | C15: 1 | D15: 1 | E15: 1 | F15: 1 | G15: 1 | H15: 1 | I15: 1 | J15: 1 | K15: 1 | L15: 1 | M15: 1 | N15: 1 | O15: 1 | P15: 1 | Q15: 1 | R15: 1 | S15: 1 | T15: 1 | U15: 1 | V15: 1
B16: September | C16: 1 | D16: 1 | E16: 1 | F16: 1 | G16: 1 | H16: 1 | I16: 1 | J16: 1 | K16: 1 | L16: 1 | M16: 1 | N16: 1 | O16: 1 | P16: 1 | Q16: 1 | R16: 1 | S16: 1 | T16: 1 | U16: 1 | V16: 1
B17: October | C17: 1 | D17: 1 | E17: 1 | F17: 1 | G17: 1 | H17: 1 | I17: 1 | J17: 1 | K17: 1 | L17: 1 | M17: 1 | N17: 1 | O17: 1 | P17: 1 | Q17: 1 | R17: 1 | S17: 1 | T17: 1 | U17: 1 | V17: 1
B18: November | C18: 1 | D18: 1 | E18: 1 | F18: 1 | G18: 1 | H18: 1 | I18: 1 | J18: 1 | K18: 1 | L18: 1 | M18: 1 | N18: 1 | O18: 1 | P18: 1 | Q18: 1 | R18: 1 | S18: 1 | T18: 1 | U18: 1 | V18: 1
B19: December | C19: 1 | D19: 1 | E19: 1 | F19: 1 | G19: 1 | H19: 1 | I19: 1 | J19: 1 | K19: 1 | L19: 1 | M19: 1 | N19: 1 | O19: 1 | P19: 1 | Q19: 1 | R19: 1 | S19: 1 | T19: 1 | U19: 1 | V19: 1
A20: 2023 | B20: January | C20: 1 | D20: 1 | E20: 1 | F20: 1 | G20: 1 | H20: 1 | I20: 1 | J20: 1 | K20: 1 | L20: 1 | M20: 1 | N20: 1 | O20: 1 | P20: 1 | Q20: 1 | R20: 1 | S20: 1 | T20: 1 | U20: 1 | V20: 1
B21: February | C21: 1 | D21: 1 | E21: 1 | F21: 1 | G21: 1 | H21: 1 | I21: 1 | J21: 1 | K21: 1 | L21: 1 | M21: 1 | N21: 1 | O21: 1 | P21: 1 | Q21: 1 | R21: 1 | S21: 1 | T21: 1 | U21: 1 | V21: 1
B22: March | C22: 1 | D22: 1 | E22: 1 | F22: 1 | G22: 1 | H22: 1 | I22: 1 | J22: 1 | K22: 1 | L22: 1 | M22: 1 | N22: 1 | O22: 1 | P22: 1 | Q22: 1 | R22: 1 | S22: 1 | T22: 1 | U22: 1 | V22: 1
B23: April | C23: 1 | D23: 1 | E23: 1 | F23: 1 | G23: 1 | H23: 1 | I23: 1 | J23: 1 | K23: 1 | L23: 1 | M23: 1 | N23: 1 | O23: 1 | P23: 1 | Q23: 1 | R23: 1 | S23: 1 | T23: 1 | U23: 1 | V23: 1
B24: May | C24: 1 | D24: 1 | E24: 1 | F24: 1 | G24: 1 | H24: 1 | I24: 1 | J24: 1 | K24: 1 | L24: 1 | M24: 1 | N24: 1 | O24: 1 | P24: 1 | Q24: 1 | R24: 1 | S24: 1 | T24: 1 | U24: 1 | V24: 1
B25: June | C25: 1 | D25: 1 | E25: 1 | F25: 1 | G25: 1 | H25: 1 | I25: 1 | J25: 1 | K25: 1 | L25: 1 | M25: 1 | N25: 1 | O25: 1 | P25: 1 | Q25: 1 | R25: 1 | S25: 1 | T25: 1 | U25: 1 | V25: 1
B26: July | C26: 1 | D26: 1 | E26: 1 | F26: 1 | G26: 1 | H26: 1 | I26: 1 | J26: 1 | K26: 1 | L26: 1 | M26: 1 | N26: 1 | O26: 1 | P26: 1 | Q26: 1 | R26: 1 | S26: 1 | T26: 1 | U26: 1 | V26: 1
B27: August | C27: 1 | D27: 1 | E27: 1 | F27: 1 | G27: 1 | H27: 1 | I27: 1 | J27: 1 | K27: 1 | L27: 1 | M27: 1 | N27: 1 | O27: 1 | P27: 1 | Q27: 1 | R27: 1 | S27: 1 | T27: 1 | U27: 1 | V27: 1
B28: September | C28: 1 | D28: 1 | E28: 1 | F28: 1 | G28: 1 | H28: 1 | I28: 1 | J28: 1 | K28: 1 | L28: 1 | M28: 1 | N28: 1 | O28: 1 | P28: 1 | Q28: 1 | R28: 1 | S28: 1 | T28: 1 | U28: 1 | V28: 1
B29: October | C29: 1 | D29: 1 | E29: 1 | F29: 1 | G29: 1 | H29: 1 | I29: 1 | J29: 1 | K29: 1 | L29: 1 | M29: 1 | N29: 1 | O29: 1 | P29: 1 | Q29: 1 | R29: 1 | S29: 1 | T29: 1 | U29: 1 | V29: 1
B30: November | C30: 1 | D30: 1 | E30: 1 | F30: 1 | G30: 1 | H30: 1 | I30: 1 | J30: 1 | K30: 1 | L30: 1 | M30: 1 | N30: 1 | O30: 1 | P30: 1 | Q30: 1 | R30: 1 | S30: 1 | T30: 1 | U30: 1 | V30: 1
B31: December | C31: 1 | D31: 1 | E31: 1 | F31: 1 | G31: 1 | H31: 1 | I31: 1 | J31: 1 | K31: 1 | L31: 1 | M31: 1 | N31: 1 | O31: 1 | P31: 1 | Q31: 1 | R31: 1 | S31: 1 | T31: 1 | U31: 1 | V31: 1
A32: 2024 | B32: January | C32: 1 | D32: 1 | E32: 1 | F32: 1 | G32: 1 | H32: 1 | I32: 1 | J32: 1 | K32: 1 | L32: 1 | M32: 1 | N32: 1 | O32: 1 | P32: 1 | Q32: 1 | R32: 1 | S32: 1 | T32: 1 | U32: 1 | V32: 1
B33: February | C33: 1 | D33: 1 | E33: 1 | F33: 1 | G33: 1 | H33: 1 | I33: 1 | J33: 1 | K33: 1 | L33: 1 | M33: 1 | N33: 1 | O33: 1 | P33: 1 | Q33: 1 | R33: 1 | S33: 1 | T33: 1 | U33: 1 | V33: 1
B34: March | C34: 1 | D34: 1 | E34: 1 | F34: 1 | G34: 1 | H34: 1 | I34: 1 | J34: 1 | K34: 1 | L34: 1 | M34: 1 | N34: 1 | O34: 1 | P34: 1 | Q34: 1 | R34: 1 | S34: 1 | T34: 1 | U34: 1 | V34: 1
B35: April | C35: 1 | D35: 1 | E35: 1 | F35: 1 | G35: 1 | H35: 1 | I35: 1 | J35: 1 | K35: 1 | L35: 1 | M35: 1 | N35: 1 | O35: 1 | P35: 1 | Q35: 1 | R35: 1 | S35: 1 | T35: 1 | U35: 1 | V35: 1
B36: May | C36: 1 | D36: 1 | E36: 1 | F36: 1 | G36: 1 | H36: 1 | I36: 1 | J36: 1 | K36: 1 | L36: 1 | M36: 1 | N36: 1 | O36: 1 | P36: 1 | Q36: 1 | R36: 1 | S36: 1 | T36: 1 | U36: 1 | V36: 1
B37: June | C37: 1 | D37: 1 | E37: 1 | F37: 1 | G37: 1 | H37: 1 | I37: 1 | J37: 1 | K37: 1 | L37: 1 | M37: 1 | N37: 1 | O37: 1 | P37: 1 | Q37: 1 | R37: 1 | S37: 1 | T37: 1 | U37: 1 | V37: 1
B38: July | C38: 1 | D38: 1 | E38: 1 | F38: 1 | G38: 1 | H38: 1 | I38: 1 | J38: 1 | K38: 1 | L38: 1 | M38: 1 | N38: 1 | O38: 1 | P38: 1 | Q38: 1 | R38: 1 | S38: 1 | T38: 1 | U38: 1 | V38: 1
B39: August | C39: 1 | D39: 1 | E39: 1 | F39: 1 | G39: 1 | H39: 1 | I39: 1 | J39: 1 | K39: 1 | L39: 1 | M39: 1 | N39: 1 | O39: 1 | P39: 1 | Q39: 1 | R39: 1 | S39: 1 | T39: 1 | U39: 1 | V39: 1
B40: September | C40: 1 | D40: 1 | E40: 1 | F40: 1 | G40: 1 | H40: 1 | I40: 1 | J40: 1 | K40: 1 | L40: 1 | M40: 1 | N40: 1 | O40: 1 | P40: 1 | Q40: 1 | R40: 1 | S40: 1 | T40: 1 | U40: 1 | V40: 1
...

Sheet Dividend Yield
C1: Bank | E1: Financial Institutions | G1: Insurance | I1: Food & Allied | L1: Miscellaneous | M1: Tannery | N1: Cement | O1: Telecommunication | P1: Pharmacuticals & Chemicals | T1: Engineering | U1: IT Sector | V1: Fuel & Power
A2: Years | B2: Months | C2: BRACBANK | D2: NCC | E2: IPDC | F2: DBH | G2: PARAMOUNT | H2: ASIAPACINS | I2: LOVELLO | J2: FINEFOODS | K2: OLYMPIC | L2: INDEXAGRO | M2: APEXFOOT | N2: CONFIDCEM | O2: GP | P2: IBNSINA | Q2: RENATA | R2: MARICO | S2: RECKITTBEN | T2: KDSALTD | U2: ADNTEL | V2: JAMUNAOIL
A3: 2021 | B3: August
B4: September | C4: ='Cash Dividend'!C4/'Price Data'!C4 -> 0 | D4: ='Cash Dividend'!D4/'Price Data'!D4 -> 0 | E4: ='Cash Dividend'!E4/'Price Data'!E4 -> 0 | F4: ='Cash Dividend'!F4/'Price Data'!F4 -> 0 | G4: ='Cash Dividend'!G4/'Price Data'!G4 -> 0 | H4: ='Cash Dividend'!H4/'Price Data'!H4 -> 0 | I4: ='Cash Dividend'!I4/'Price Data'!I4 -> 0 | J4: ='Cash Dividend'!J4/'Price Data'!J4 -> 0 | ... V4: ='Cash Dividend'!V4/'Price Data'!V4 -> 0
B5: October | C5: ='Cash Dividend'!C5/'Price Data'!C5 -> 0 | D5: ='Cash Dividend'!D5/'Price Data'!D5 -> 0 | E5: ='Cash Dividend'!E5/'Price Data'!E5 -> 0 | F5: ='Cash Dividend'!F5/'Price Data'!F5 -> 0 | G5: ='Cash Dividend'!G5/'Price Data'!G5 -> 0 | H5: ='Cash Dividend'!H5/'Price Data'!H5 -> 0 | I5: ='Cash Dividend'!I5/'Price Data'!I5 -> 0 | J5: ='Cash Dividend'!J5/'Price Data'!J5 -> 0 | ... V5: ='Cash Dividend'!V5/'Price Data'!V5 -> 0
B6: November | C6: ='Cash Dividend'!C6/'Price Data'!C6 -> 0 | D6: ='Cash Dividend'!D6/'Price Data'!D6 -> 0 | E6: ='Cash Dividend'!E6/'Price Data'!E6 -> 0 | F6: ='Cash Dividend'!F6/'Price Data'!F6 -> 0 | G6: ='Cash Dividend'!G6/'Price Data'!G6 -> 0 | H6: ='Cash Dividend'!H6/'Price Data'!H6 -> 0 | I6: ='Cash Dividend'!I6/'Price Data'!I6 -> 0.032884903 | J6: ='Cash Dividend'!J6/'Price Data'!J6 -> 0 | ... V6: ='Cash Dividend'!V6/'Price Data'!V6 -> 0
B7: December | C7: ='Cash Dividend'!C7/'Price Data'!C7 -> 0 | D7: ='Cash Dividend'!D7/'Price Data'!D7 -> 0 | E7: ='Cash Dividend'!E7/'Price Data'!E7 -> 0 | F7: ='Cash Dividend'!F7/'Price Data'!F7 -> 0 | G7: ='Cash Dividend'!G7/'Price Data'!G7 -> 0 | H7: ='Cash Dividend'!H7/'Price Data'!H7 -> 0 | I7: ='Cash Dividend'!I7/'Price Data'!I7 -> 0 | J7: ='Cash Dividend'!J7/'Price Data'!J7 -> 0 | ... V7: ='Cash Dividend'!V7/'Price Data'!V7 -> 0
A8: 2022 | B8: January | C8: ='Cash Dividend'!C8/'Price Data'!C8 -> 0 | D8: ='Cash Dividend'!D8/'Price Data'!D8 -> 0 | E8: ='Cash Dividend'!E8/'Price Data'!E8 -> 0 | F8: ='Cash Dividend'!F8/'Price Data'!F8 -> 0 | G8: ='Cash Dividend'!G8/'Price Data'!G8 -> 0 | H8: ='Cash Dividend'!H8/'Price Data'!H8 -> 0 | I8: ='Cash Dividend'!I8/'Price Data'!I8 -> 0 | J8: ='Cash Dividend'!J8/'Price Data'!J8 -> 0 | ... V8: ='Cash Dividend'!V8/'Price Data'!V8 -> 0.071513707
B9: February | C9: ='Cash Dividend'!C9/'Price Data'!C9 -> 0 | D9: ='Cash Dividend'!D9/'Price Data'!D9 -> 0 | E9: ='Cash Dividend'!E9/'Price Data'!E9 -> 0 | F9: ='Cash Dividend'!F9/'Price Data'!F9 -> 0 | G9: ='Cash Dividend'!G9/'Price Data'!G9 -> 0 | H9: ='Cash Dividend'!H9/'Price Data'!H9 -> 0 | I9: ='Cash Dividend'!I9/'Price Data'!I9 -> 0 | J9: ='Cash Dividend'!J9/'Price Data'!J9 -> 0 | ... V9: ='Cash Dividend'!V9/'Price Data'!V9 -> 0
B10: March | C10: ='Cash Dividend'!C10/'Price Data'!C10 -> 0 | D10: ='Cash Dividend'!D10/'Price Data'!D10 -> 0 | E10: ='Cash Dividend'!E10/'Price Data'!E10 -> 0.03051106 | F10: ='Cash Dividend'!F10/'Price Data'!F10 -> 0.022865854 | G10: ='Cash Dividend'!G10/'Price Data'!G10 -> 0 | H10: ='Cash Dividend'!H10/'Price Data'!H10 -> 0 | I10: ='Cash Dividend'!I10/'Price Data'!I10 -> 0 | J10: ='Cash Dividend'!J10/'Price Data'!J10 -> 0 | ... V10: ='Cash Dividend'!V10/'Price Data'!V10 -> 0
B11: April | C11: ='Cash Dividend'!C11/'Price Data'!C11 -> 0.023205446 | D11: ='Cash Dividend'!D11/'Price Data'!D11 -> 0 | E11: ='Cash Dividend'!E11/'Price Data'!E11 -> 0 | F11: ='Cash Dividend'!F11/'Price Data'!F11 -> 0 | G11: ='Cash Dividend'!G11/'Price Data'!G11 -> 0.017513135 | H11: ='Cash Dividend'!H11/'Price Data'!H11 -> 0 | I11: ='Cash Dividend'!I11/'Price Data'!I11 -> 0 | J11: ='Cash Dividend'!J11/'Price Data'!J11 -> 0 | ... V11: ='Cash Dividend'!V11/'Price Data'!V11 -> 0
B12: May | C12: ='Cash Dividend'!C12/'Price Data'!C12 -> 0 | D12: ='Cash Dividend'!D12/'Price Data'!D12 -> 0 | E12: ='Cash Dividend'!E12/'Price Data'!E12 -> 0 | F12: ='Cash Dividend'!F12/'Price Data'!F12 -> 0 | G12: ='Cash Dividend'!G12/'Price Data'!G12 -> 0 | H12: ='Cash Dividend'!H12/'Price Data'!H12 -> 0.034682081 | I12: ='Cash Dividend'!I12/'Price Data'!I12 -> 0 | J12: ='Cash Dividend'!J12/'Price Data'!J12 -> 0 | ... V12: ='Cash Dividend'!V12/'Price Data'!V12 -> 0
B13: June | C13: ='Cash Dividend'!C13/'Price Data'!C13 -> 0 | D13: ='Cash Dividend'!D13/'Price Data'!D13 -> 0.083333333 | E13: ='Cash Dividend'!E13/'Price Data'!E13 -> 0 | F13: ='Cash Dividend'!F13/'Price Data'!F13 -> 0 | G13: ='Cash Dividend'!G13/'Price Data'!G13 -> 0 | H13: ='Cash Dividend'!H13/'Price Data'!H13 -> 0 | I13: ='Cash Dividend'!I13/'Price Data'!I13 -> 0 | J13: ='Cash Dividend'!J13/'Price Data'!J13 -> 0 | ... V13: ='Cash Dividend'!V13/'Price Data'!V13 -> 0
B14: July | C14: ='Cash Dividend'!C14/'Price Data'!C14 -> 0 | D14: ='Cash Dividend'!D14/'Price Data'!D14 -> 0 | E14: ='Cash Dividend'!E14/'Price Data'!E14 -> 0 | F14: ='Cash Dividend'!F14/'Price Data'!F14 -> 0 | G14: ='Cash Dividend'!G14/'Price Data'!G14 -> 0 | H14: ='Cash Dividend'!H14/'Price Data'!H14 -> 0 | I14: ='Cash Dividend'!I14/'Price Data'!I14 -> 0 | J14: ='Cash Dividend'!J14/'Price Data'!J14 -> 0 | ... V14: ='Cash Dividend'!V14/'Price Data'!V14 -> 0
B15: August | C15: ='Cash Dividend'!C15/'Price Data'!C15 -> 0 | D15: ='Cash Dividend'!D15/'Price Data'!D15 -> 0 | E15: ='Cash Dividend'!E15/'Price Data'!E15 -> 0 | F15: ='Cash Dividend'!F15/'Price Data'!F15 -> 0 | G15: ='Cash Dividend'!G15/'Price Data'!G15 -> 0 | H15: ='Cash Dividend'!H15/'Price Data'!H15 -> 0 | I15: ='Cash Dividend'!I15/'Price Data'!I15 -> 0 | J15: ='Cash Dividend'!J15/'Price Data'!J15 -> 0 | ... V15: ='Cash Dividend'!V15/'Price Data'!V15 -> 0
B16: September | C16: ='Cash Dividend'!C16/'Price Data'!C16 -> 0 | D16: ='Cash Dividend'!D16/'Price Data'!D16 -> 0 | E16: ='Cash Dividend'!E16/'Price Data'!E16 -> 0 | F16: ='Cash Dividend'!F16/'Price Data'!F16 -> 0 | G16: ='Cash Dividend'!G16/'Price Data'!G16 -> 0 | H16: ='Cash Dividend'!H16/'Price Data'!H16 -> 0 | I16: ='Cash Dividend'!I16/'Price Data'!I16 -> 0 | J16: ='Cash Dividend'!J16/'Price Data'!J16 -> 0 | ... V16: ='Cash Dividend'!V16/'Price Data'!V16 -> 0
B17: October | C17: ='Cash Dividend'!C17/'Price Data'!C17 -> 0 | D17: ='Cash Dividend'!D17/'Price Data'!D17 -> 0 | E17: ='Cash Dividend'!E17/'Price Data'!E17 -> 0 | F17: ='Cash Dividend'!F17/'Price Data'!F17 -> 0 | G17: ='Cash Dividend'!G17/'Price Data'!G17 -> 0 | H17: ='Cash Dividend'!H17/'Price Data'!H17 -> 0 | I17: ='Cash Dividend'!I17/'Price Data'!I17 -> 0 | J17: ='Cash Dividend'!J17/'Price Data'!J17 -> 0 | ... V17: ='Cash Dividend'!V17/'Price Data'!V17 -> 0
B18: November | C18: ='Cash Dividend'!C18/'Price Data'!C18 -> 0 | D18: ='Cash Dividend'!D18/'Price Data'!D18 -> 0 | E18: ='Cash Dividend'!E18/'Price Data'!E18 -> 0 | F18: ='Cash Dividend'!F18/'Price Data'!F18 -> 0 | G18: ='Cash Dividend'!G18/'Price Data'!G18 -> 0 | H18: ='Cash Dividend'!H18/'Price Data'!H18 -> 0 | I18: ='Cash Dividend'!I18/'Price Data'!I18 -> 0.034833091 | J18: ='Cash Dividend'!J18/'Price Data'!J18 -> 0.0025773196 | ... V18: ='Cash Dividend'!V18/'Price Data'!V18 -> 0
B19: December | C19: ='Cash Dividend'!C19/'Price Data'!C19 -> 0 | D19: ='Cash Dividend'!D19/'Price Data'!D19 -> 0 | E19: ='Cash Dividend'!E19/'Price Data'!E19 -> 0 | F19: ='Cash Dividend'!F19/'Price Data'!F19 -> 0 | G19: ='Cash Dividend'!G19/'Price Data'!G19 -> 0 | H19: ='Cash Dividend'!H19/'Price Data'!H19 -> 0 | I19: ='Cash Dividend'!I19/'Price Data'!I19 -> 0 | J19: ='Cash Dividend'!J19/'Price Data'!J19 -> 0 | ... V19: ='Cash Dividend'!V19/'Price Data'!V19 -> 0.071727436
A20: 2023 | B20: January | C20: ='Cash Dividend'!C20/'Price Data'!C20 -> 0 | D20: ='Cash Dividend'!D20/'Price Data'!D20 -> 0 | E20: ='Cash Dividend'!E20/'Price Data'!E20 -> 0 | F20: ='Cash Dividend'!F20/'Price Data'!F20 -> 0 | G20: ='Cash Dividend'!G20/'Price Data'!G20 -> 0 | H20: ='Cash Dividend'!H20/'Price Data'!H20 -> 0 | I20: ='Cash Dividend'!I20/'Price Data'!I20 -> 0 | J20: ='Cash Dividend'!J20/'Price Data'!J20 -> 0 | ... V20: ='Cash Dividend'!V20/'Price Data'!V20 -> 0
B21: February | C21: ='Cash Dividend'!C21/'Price Data'!C21 -> 0 | D21: ='Cash Dividend'!D21/'Price Data'!D21 -> 0 | E21: ='Cash Dividend'!E21/'Price Data'!E21 -> 0 | F21: ='Cash Dividend'!F21/'Price Data'!F21 -> 0 | G21: ='Cash Dividend'!G21/'Price Data'!G21 -> 0 | H21: ='Cash Dividend'!H21/'Price Data'!H21 -> 0 | I21: ='Cash Dividend'!I21/'Price Data'!I21 -> 0 | J21: ='Cash Dividend'!J21/'Price Data'!J21 -> 0 | ... V21: ='Cash Dividend'!V21/'Price Data'!V21 -> 0
B22: March | C22: ='Cash Dividend'!C22/'Price Data'!C22 -> 0 | D22: ='Cash Dividend'!D22/'Price Data'!D22 -> 0 | E22: ='Cash Dividend'!E22/'Price Data'!E22 -> 0.018228217 | F22: ='Cash Dividend'!F22/'Price Data'!F22 -> 0 | G22: ='Cash Dividend'!G22/'Price Data'!G22 -> 0 | H22: ='Cash Dividend'!H22/'Price Data'!H22 -> 0 | I22: ='Cash Dividend'!I22/'Price Data'!I22 -> 0 | J22: ='Cash Dividend'!J22/'Price Data'!J22 -> 0 | ... V22: ='Cash Dividend'!V22/'Price Data'!V22 -> 0
B23: April | C23: ='Cash Dividend'!C23/'Price Data'!C23 -> 0 | D23: ='Cash Dividend'!D23/'Price Data'!D23 -> 0 | E23: ='Cash Dividend'!E23/'Price Data'!E23 -> 0 | F23: ='Cash Dividend'!F23/'Price Data'!F23 -> 0.026455026 | G23: ='Cash Dividend'!G23/'Price Data'!G23 -> 0 | H23: ='Cash Dividend'!H23/'Price Data'!H23 -> 0 | I23: ='Cash Dividend'!I23/'Price Data'!I23 -> 0 | J23: ='Cash Dividend'!J23/'Price Data'!J23 -> 0 | ... V23: ='Cash Dividend'!V23/'Price Data'!V23 -> 0
B24: May | C24: ='Cash Dividend'!C24/'Price Data'!C24 -> 0.029809221 | D24: ='Cash Dividend'!D24/'Price Data'!D24 -> 0 | E24: ='Cash Dividend'!E24/'Price Data'!E24 -> 0 | F24: ='Cash Dividend'!F24/'Price Data'!F24 -> 0 | G24: ='Cash Dividend'!G24/'Price Data'!G24 -> 0.017271157 | H24: ='Cash Dividend'!H24/'Price Data'!H24 -> 0.027322404 | I24: ='Cash Dividend'!I24/'Price Data'!I24 -> 0 | J24: ='Cash Dividend'!J24/'Price Data'!J24 -> 0 | ... V24: ='Cash Dividend'!V24/'Price Data'!V24 -> 0
B25: June | C25: ='Cash Dividend'!C25/'Price Data'!C25 -> 0 | D25: ='Cash Dividend'!D25/'Price Data'!D25 -> 0.038167939 | E25: ='Cash Dividend'!E25/'Price Data'!E25 -> 0 | F25: ='Cash Dividend'!F25/'Price Data'!F25 -> 0 | G25: ='Cash Dividend'!G25/'Price Data'!G25 -> 0 | H25: ='Cash Dividend'!H25/'Price Data'!H25 -> 0 | I25: ='Cash Dividend'!I25/'Price Data'!I25 -> 0 | J25: ='Cash Dividend'!J25/'Price Data'!J25 -> 0 | ... V25: ='Cash Dividend'!V25/'Price Data'!V25 -> 0
B26: July | C26: ='Cash Dividend'!C26/'Price Data'!C26 -> 0 | D26: ='Cash Dividend'!D26/'Price Data'!D26 -> 0 | E26: ='Cash Dividend'!E26/'Price Data'!E26 -> 0 | F26: ='Cash Dividend'!F26/'Price Data'!F26 -> 0 | G26: ='Cash Dividend'!G26/'Price Data'!G26 -> 0 | H26: ='Cash Dividend'!H26/'Price Data'!H26 -> 0 | I26: ='Cash Dividend'!I26/'Price Data'!I26 -> 0 | J26: ='Cash Dividend'!J26/'Price Data'!J26 -> 0 | ... V26: ='Cash Dividend'!V26/'Price Data'!V26 -> 0
B27: August | C27: ='Cash Dividend'!C27/'Price Data'!C27 -> 0 | D27: ='Cash Dividend'!D27/'Price Data'!D27 -> 0 | E27: ='Cash Dividend'!E27/'Price Data'!E27 -> 0 | F27: ='Cash Dividend'!F27/'Price Data'!F27 -> 0 | G27: ='Cash Dividend'!G27/'Price Data'!G27 -> 0 | H27: ='Cash Dividend'!H27/'Price Data'!H27 -> 0 | I27: ='Cash Dividend'!I27/'Price Data'!I27 -> 0 | J27: ='Cash Dividend'!J27/'Price Data'!J27 -> 0 | ... V27: ='Cash Dividend'!V27/'Price Data'!V27 -> 0
B28: September | C28: ='Cash Dividend'!C28/'Price Data'!C28 -> 0 | D28: ='Cash Dividend'!D28/'Price Data'!D28 -> 0 | E28: ='Cash Dividend'!E28/'Price Data'!E28 -> 0 | F28: ='Cash Dividend'!F28/'Price Data'!F28 -> 0 | G28: ='Cash Dividend'!G28/'Price Data'!G28 -> 0 | H28: ='Cash Dividend'!H28/'Price Data'!H28 -> 0 | I28: ='Cash Dividend'!I28/'Price Data'!I28 -> 0 | J28: ='Cash Dividend'!J28/'Price Data'!J28 -> 0 | ... V28: ='Cash Dividend'!V28/'Price Data'!V28 -> 0
B29: October | C29: ='Cash Dividend'!C29/'Price Data'!C29 -> 0 | D29: ='Cash Dividend'!D29/'Price Data'!D29 -> 0 | E29: ='Cash Dividend'!E29/'Price Data'!E29 -> 0 | F29: ='Cash Dividend'!F29/'Price Data'!F29 -> 0 | G29: ='Cash Dividend'!G29/'Price Data'!G29 -> 0 | H29: ='Cash Dividend'!H29/'Price Data'!H29 -> 0 | I29: ='Cash Dividend'!I29/'Price Data'!I29 -> 0 | J29: ='Cash Dividend'!J29/'Price Data'!J29 -> 0 | ... V29: ='Cash Dividend'!V29/'Price Data'!V29 -> 0
B30: November | C30: ='Cash Dividend'!C30/'Price Data'!C30 -> 0 | D30: ='Cash Dividend'!D30/'Price Data'!D30 -> 0 | E30: ='Cash Dividend'!E30/'Price Data'!E30 -> 0 | F30: ='Cash Dividend'!F30/'Price Data'!F30 -> 0 | G30: ='Cash Dividend'!G30/'Price Data'!G30 -> 0 | H30: ='Cash Dividend'!H30/'Price Data'!H30 -> 0 | I30: ='Cash Dividend'!I30/'Price Data'!I30 -> 0.029027576 | J30: ='Cash Dividend'!J30/'Price Data'!J30 -> 0.0010179153 | ... V30: ='Cash Dividend'!V30/'Price Data'!V30 -> 0
B31: December | C31: ='Cash Dividend'!C31/'Price Data'!C31 -> 0 | D31: ='Cash Dividend'!D31/'Price Data'!D31 -> 0 | E31: ='Cash Dividend'!E31/'Price Data'!E31 -> 0 | F31: ='Cash Dividend'!F31/'Price Data'!F31 -> 0 | G31: ='Cash Dividend'!G31/'Price Data'!G31 -> 0 | H31: ='Cash Dividend'!H31/'Price Data'!H31 -> 0 | I31: ='Cash Dividend'!I31/'Price Data'!I31 -> 0 | J31: ='Cash Dividend'!J31/'Price Data'!J31 -> 0 | ... V31: ='Cash Dividend'!V31/'Price Data'!V31 -> 0.077151335
A32: 2024 | B32: January | C32: ='Cash Dividend'!C32/'Price Data'!C32 -> 0 | D32: ='Cash Dividend'!D32/'Price Data'!D32 -> 0 | E32: ='Cash Dividend'!E32/'Price Data'!E32 -> 0 | F32: ='Cash Dividend'!F32/'Price Data'!F32 -> 0 | G32: ='Cash Dividend'!G32/'Price Data'!G32 -> 0 | H32: ='Cash Dividend'!H32/'Price Data'!H32 -> 0 | I32: ='Cash Dividend'!I32/'Price Data'!I32 -> 0 | J32: ='Cash Dividend'!J32/'Price Data'!J32 -> 0 | ... V32: ='Cash Dividend'!V32/'Price Data'!V32 -> 0
B33: February | C33: ='Cash Dividend'!C33/'Price Data'!C33 -> 0 | D33: ='Cash Dividend'!D33/'Price Data'!D33 -> 0 | E33: ='Cash Dividend'!E33/'Price Data'!E33 -> 0 | F33: ='Cash Dividend'!F33/'Price Data'!F33 -> 0 | G33: ='Cash Dividend'!G33/'Price Data'!G33 -> 0 | H33: ='Cash Dividend'!H33/'Price Data'!H33 -> 0 | I33: ='Cash Dividend'!I33/'Price Data'!I33 -> 0 | J33: ='Cash Dividend'!J33/'Price Data'!J33 -> 0 | ... V33: ='Cash Dividend'!V33/'Price Data'!V33 -> 0
B34: March | C34: ='Cash Dividend'!C34/'Price Data'!C34 -> 0 | D34: ='Cash Dividend'!D34/'Price Data'!D34 -> 0 | E34: ='Cash Dividend'!E34/'Price Data'!E34 -> 0 | F34: ='Cash Dividend'!F34/'Price Data'!F34 -> 0 | G34: ='Cash Dividend'!G34/'Price Data'!G34 -> 0 | H34: ='Cash Dividend'!H34/'Price Data'!H34 -> 0 | I34: ='Cash Dividend'!I34/'Price Data'!I34 -> 0 | J34: ='Cash Dividend'!J34/'Price Data'!J34 -> 0 | ... V34: ='Cash Dividend'!V34/'Price Data'!V34 -> 0
B35: April | C35: ='Cash Dividend'!C35/'Price Data'!C35 -> 0 | D35: ='Cash Dividend'!D35/'Price Data'!D35 -> 0 | E35: ='Cash Dividend'!E35/'Price Data'!E35 -> 0.024084778 | F35: ='Cash Dividend'!F35/'Price Data'!F35 -> 0.040431267 | G35: ='Cash Dividend'!G35/'Price Data'!G35 -> 0 | H35: ='Cash Dividend'!H35/'Price Data'!H35 -> 0 | I35: ='Cash Dividend'!I35/'Price Data'!I35 -> 0 | J35: ='Cash Dividend'!J35/'Price Data'!J35 -> 0 | ... V35: ='Cash Dividend'!V35/'Price Data'!V35 -> 0
B36: May | C36: ='Cash Dividend'!C36/'Price Data'!C36 -> 0.038387716 | D36: ='Cash Dividend'!D36/'Price Data'!D36 -> 0 | E36: ='Cash Dividend'!E36/'Price Data'!E36 -> 0 | F36: ='Cash Dividend'!F36/'Price Data'!F36 -> 0 | G36: ='Cash Dividend'!G36/'Price Data'!G36 -> 0.018315018 | H36: ='Cash Dividend'!H36/'Price Data'!H36 -> 0.030534351 | I36: ='Cash Dividend'!I36/'Price Data'!I36 -> 0 | J36: ='Cash Dividend'!J36/'Price Data'!J36 -> 0 | ... V36: ='Cash Dividend'!V36/'Price Data'!V36 -> 0
B37: June | C37: ='Cash Dividend'!C37/'Price Data'!C37 -> 0 | D37: ='Cash Dividend'!D37/'Price Data'!D37 -> 0.12244898 | E37: ='Cash Dividend'!E37/'Price Data'!E37 -> 0 | F37: ='Cash Dividend'!F37/'Price Data'!F37 -> 0 | G37: ='Cash Dividend'!G37/'Price Data'!G37 -> 0 | H37: ='Cash Dividend'!H37/'Price Data'!H37 -> 0 | I37: ='Cash Dividend'!I37/'Price Data'!I37 -> 0 | J37: ='Cash Dividend'!J37/'Price Data'!J37 -> 0 | ... V37: ='Cash Dividend'!V37/'Price Data'!V37 -> 0
B38: July | C38: ='Cash Dividend'!C38/'Price Data'!C38 -> 0 | D38: ='Cash Dividend'!D38/'Price Data'!D38 -> 0 | E38: ='Cash Dividend'!E38/'Price Data'!E38 -> 0 | F38: ='Cash Dividend'!F38/'Price Data'!F38 -> 0 | G38: ='Cash Dividend'!G38/'Price Data'!G38 -> 0 | H38: ='Cash Dividend'!H38/'Price Data'!H38 -> 0 | I38: ='Cash Dividend'!I38/'Price Data'!I38 -> 0 | J38: ='Cash Dividend'!J38/'Price Data'!J38 -> 0 | ... V38: ='Cash Dividend'!V38/'Price Data'!V38 -> 0
B39: August | C39: ='Cash Dividend'!C39/'Price Data'!C39 -> 0 | D39: ='Cash Dividend'!D39/'Price Data'!D39 -> 0 | E39: ='Cash Dividend'!E39/'Price Data'!E39 -> 0 | F39: ='Cash Dividend'!F39/'Price Data'!F39 -> 0 | G39: ='Cash Dividend'!G39/'Price Data'!G39 -> 0 | H39: ='Cash Dividend'!H39/'Price Data'!H39 -> 0 | I39: ='Cash Dividend'!I39/'Price Data'!I39 -> 0 | J39: ='Cash Dividend'!J39/'Price Data'!J39 -> 0 | ... V39: ='Cash Dividend'!V39/'Price Data'!V39 -> 0
B40: September | C40: ='Cash Dividend'!C40/'Price Data'!C40 -> 0 | D40: ='Cash Dividend'!D40/'Price Data'!D40 -> 0 | E40: ='Cash Dividend'!E40/'Price Data'!E40 -> 0 | F40: ='Cash Dividend'!F40/'Price Data'!F40 -> 0 | G40: ='Cash Dividend'!G40/'Price Data'!G40 -> 0 | H40: ='Cash Dividend'!H40/'Price Data'!H40 -> 0 | I40: ='Cash Dividend'!I40/'Price Data'!I40 -> 0 | J40: ='Cash Dividend'!J40/'Price Data'!J40 -> 0 | ... V40: ='Cash Dividend'!V40/'Price Data'!V40 -> 0
...

Sheet Capital Gain
C1: Bank | E1: Financial Institutions | G1: Insurance | I1: Food & Allied | L1: Miscellaneous | M1: Tannery | N1: Cement | O1: Telecommunication | P1: Pharmacuticals & Chemicals | T1: Engineering | U1: IT Sector | V1: Fuel & Power
A2: Years | B2: Months | C2: BRACBANK | D2: NCC | E2: IPDC | F2: DBH | G2: PARAMOUNT | H2: ASIAPACINS | I2: LOVELLO | J2: FINEFOODS | K2: OLYMPIC | L2: INDEXAGRO | M2: APEXFOOT | N2: CONFIDCEM | O2: GP | P2: IBNSINA | Q2: RENATA | R2: MARICO | S2: RECKITTBEN | T2: KDSALTD | U2: ADNTEL | V2: JAMUNAOIL
A3: 2021 | B3: August
B4: September | C4: =('Price Data'!C4*(1+'Stock Dividend'!C4+'Right Share Ratio'!C4)*Split!C4-'Price Data'!C3-'Right Share Ratio'!C4*'Right Share Offer Price'!C4*Split!C4)/'Price Data'!C3 -> 0.010392985 | D4: =('Price Data'!D4*(1+'Stock Dividend'!D4+'Right Share Ratio'!D4)*Split!D4-'Price Data'!D3-'Right Share Ratio'!D4*'Right Share Offer Price'!D4*Split!D4)/'Price Data'!D3 -> 0.0064102564 | E4: =('Price Data'!E4*(1+'Stock Dividend'!E4+'Right Share Ratio'!E4)*Split!E4-'Price Data'!E3-'Right Share Ratio'!E4*'Right Share Offer Price'!E4*Split!E4)/'Price Data'!E3 -> 0.25583288 | F4: =('Price Data'!F4*(1+'Stock Dividend'!F4+'Right Share Ratio'!F4)*Split!F4-'Price Data'!F3-'Right Share Ratio'!F4*'Right Share Offer Price'!F4*Split!F4)/'Price Data'!F3 -> 0.049779205 | G4: =('Price Data'!G4*(1+'Stock Dividend'!G4+'Right Share Ratio'!G4)*Split!G4-'Price Data'!G3-'Right Share Ratio'!G4*'Right Share Offer Price'!G4*Split!G4)/'Price Data'!G3 -> -0.063901345 | H4: =('Price Data'!H4*(1+'Stock Dividend'!H4+'Right Share Ratio'!H4)*Split!H4-'Price Data'!H3-'Right Share Ratio'!H4*'Right Share Offer Price'!H4*Split!H4)/'Price Data'!H3 -> -0.032394366 | I4: =('Price Data'!I4*(1+'Stock Dividend'!I4+'Right Share Ratio'!I4)*Split!I4-'Price Data'!I3-'Right Share Ratio'!I4*'Right Share Offer Price'!I4*Split!I4)/'Price Data'!I3 -> 0.05820275 | J4: =('Price Data'!J4*(1+'Stock Dividend'!J4+'Right Share Ratio'!J4)*Split!J4-'Price Data'!J3-'Right Share Ratio'!J4*'Right Share Offer Price'!J4*Split!J4)/'Price Data'!J3 -> -0.049557522 | ... V4: =('Price Data'!V4*(1+'Stock Dividend'!V4+'Right Share Ratio'!V4)*Split!V4-'Price Data'!V3-'Right Share Ratio'!V4*'Right Share Offer Price'!V4*Split!V4)/'Price Data'!V3 -> 0.0054674686
B5: October | C5: =('Price Data'!C5*(1+'Stock Dividend'!C5+'Right Share Ratio'!C5)*Split!C5-'Price Data'!C4-'Right Share Ratio'!C5*'Right Share Offer Price'!C5*Split!C5)/'Price Data'!C4 -> -0.037608486 | D5: =('Price Data'!D5*(1+'Stock Dividend'!D5+'Right Share Ratio'!D5)*Split!D5-'Price Data'!D4-'Right Share Ratio'!D5*'Right Share Offer Price'!D5*Split!D5)/'Price Data'!D4 -> -0.012738854 | E5: =('Price Data'!E5*(1+'Stock Dividend'!E5+'Right Share Ratio'!E5)*Split!E5-'Price Data'!E4-'Right Share Ratio'!E5*'Right Share Offer Price'!E5*Split!E5)/'Price Data'!E4 -> -0.14625189 | F5: =('Price Data'!F5*(1+'Stock Dividend'!F5+'Right Share Ratio'!F5)*Split!F5-'Price Data'!F4-'Right Share Ratio'!F5*'Right Share Offer Price'!F5*Split!F5)/'Price Data'!F4 -> -0.070618228 | G5: =('Price Data'!G5*(1+'Stock Dividend'!G5+'Right Share Ratio'!G5)*Split!G5-'Price Data'!G4-'Right Share Ratio'!G5*'Right Share Offer Price'!G5*Split!G5)/'Price Data'!G4 -> -0.05988024 | H5: =('Price Data'!H5*(1+'Stock Dividend'!H5+'Right Share Ratio'!H5)*Split!H5-'Price Data'!H4-'Right Share Ratio'!H5*'Right Share Offer Price'!H5*Split!H5)/'Price Data'!H4 -> -0.013100437 | I5: =('Price Data'!I5*(1+'Stock Dividend'!I5+'Right Share Ratio'!I5)*Split!I5-'Price Data'!I4-'Right Share Ratio'!I5*'Right Share Offer Price'!I5*Split!I5)/'Price Data'!I4 -> -0.022061046 | J5: =('Price Data'!J5*(1+'Stock Dividend'!J5+'Right Share Ratio'!J5)*Split!J5-'Price Data'!J4-'Right Share Ratio'!J5*'Right Share Offer Price'!J5*Split!J5)/'Price Data'!J4 -> -0.23091248 | ... V5: =('Price Data'!V5*(1+'Stock Dividend'!V5+'Right Share Ratio'!V5)*Split!V5-'Price Data'!V4-'Right Share Ratio'!V5*'Right Share Offer Price'!V5*Split!V5)/'Price Data'!V4 -> -0.057096248
B6: November | C6: =('Price Data'!C6*(1+'Stock Dividend'!C6+'Right Share Ratio'!C6)*Split!C6-'Price Data'!C5-'Right Share Ratio'!C6*'Right Share Offer Price'!C6*Split!C6)/'Price Data'!C5 -> 0.18336673 | D6: =('Price Data'!D6*(1+'Stock Dividend'!D6+'Right Share Ratio'!D6)*Split!D6-'Price Data'!D5-'Right Share Ratio'!D6*'Right Share Offer Price'!D6*Split!D6)/'Price Data'!D5 -> -0.0064516129 | E6: =('Price Data'!E6*(1+'Stock Dividend'!E6+'Right Share Ratio'!E6)*Split!E6-'Price Data'!E5-'Right Share Ratio'!E6*'Right Share Offer Price'!E6*Split!E6)/'Price Data'!E5 -> -0.057692308 | F6: =('Price Data'!F6*(1+'Stock Dividend'!F6+'Right Share Ratio'!F6)*Split!F6-'Price Data'!F5-'Right Share Ratio'!F6*'Right Share Offer Price'!F6*Split!F6)/'Price Data'!F5 -> -0.037443423 | G6: =('Price Data'!G6*(1+'Stock Dividend'!G6+'Right Share Ratio'!G6)*Split!G6-'Price Data'!G5-'Right Share Ratio'!G6*'Right Share Offer Price'!G6*Split!G6)/'Price Data'!G5 -> -0.095541401 | H6: =('Price Data'!H6*(1+'Stock Dividend'!H6+'Right Share Ratio'!H6)*Split!H6-'Price Data'!H5-'Right Share Ratio'!H6*'Right Share Offer Price'!H6*Split!H6)/'Price Data'!H5 -> -0.095870206 | I6: =('Price Data'!I6*(1+'Stock Dividend'!I6+'Right Share Ratio'!I6)*Split!I6-'Price Data'!I5-'Right Share Ratio'!I6*'Right Share Offer Price'!I6*Split!I6)/'Price Data'!I5 -> 0.03368356 | J6: =('Price Data'!J6*(1+'Stock Dividend'!J6+'Right Share Ratio'!J6)*Split!J6-'Price Data'!J5-'Right Share Ratio'!J6*'Right Share Offer Price'!J6*Split!J6)/'Price Data'!J5 -> -0.079903148 | ... V6: =('Price Data'!V6*(1+'Stock Dividend'!V6+'Right Share Ratio'!V6)*Split!V6-'Price Data'!V5-'Right Share Ratio'!V6*'Right Share Offer Price'!V6*Split!V6)/'Price Data'!V5 -> -0.01384083
B7: December | C7: =('Price Data'!C7*(1+'Stock Dividend'!C7+'Right Share Ratio'!C7)*Split!C7-'Price Data'!C6-'Right Share Ratio'!C7*'Right Share Offer Price'!C7*Split!C7)/'Price Data'!C6 -> 0.020321761 | D7: =('Price Data'!D7*(1+'Stock Dividend'!D7+'Right Share Ratio'!D7)*Split!D7-'Price Data'!D6-'Right Share Ratio'!D7*'Right Share Offer Price'!D7*Split!D7)/'Price Data'!D6 -> -0.0064935065 | E7: =('Price Data'!E7*(1+'Stock Dividend'!E7+'Right Share Ratio'!E7)*Split!E7-'Price Data'!E6-'Right Share Ratio'!E7*'Right Share Offer Price'!E7*Split!E7)/'Price Data'!E6 -> -0.012889366 | F7: =('Price Data'!F7*(1+'Stock Dividend'!F7+'Right Share Ratio'!F7)*Split!F7-'Price Data'!F6-'Right Share Ratio'!F7*'Right Share Offer Price'!F7*Split!F7)/'Price Data'!F6 -> -0.0012824166 | G7: =('Price Data'!G7*(1+'Stock Dividend'!G7+'Right Share Ratio'!G7)*Split!G7-'Price Data'!G6-'Right Share Ratio'!G7*'Right Share Offer Price'!G7*Split!G7)/'Price Data'!G6 -> 0.032394366 | H7: =('Price Data'!H7*(1+'Stock Dividend'!H7+'Right Share Ratio'!H7)*Split!H7-'Price Data'!H6-'Right Share Ratio'!H7*'Right Share Offer Price'!H7*Split!H7)/'Price Data'!H6 -> 0.11745514 | I7: =('Price Data'!I7*(1+'Stock Dividend'!I7+'Right Share Ratio'!I7)*Split!I7-'Price Data'!I6-'Right Share Ratio'!I7*'Right Share Offer Price'!I7*Split!I7)/'Price Data'!I6 -> -0.086696562 | J7: =('Price Data'!J7*(1+'Stock Dividend'!J7+'Right Share Ratio'!J7)*Split!J7-'Price Data'!J6-'Right Share Ratio'!J7*'Right Share Offer Price'!J7*Split!J7)/'Price Data'!J6 -> 0.32631579 | ... V7: =('Price Data'!V7*(1+'Stock Dividend'!V7+'Right Share Ratio'!V7)*Split!V7-'Price Data'!V6-'Right Share Ratio'!V7*'Right Share Offer Price'!V7*Split!V7)/'Price Data'!V6 -> 0.00058479532
A8: 2022 | B8: January | C8: =('Price Data'!C8*(1+'Stock Dividend'!C8+'Right Share Ratio'!C8)*Split!C8-'Price Data'!C7-'Right Share Ratio'!C8*'Right Share Offer Price'!C8*Split!C8)/'Price Data'!C7 -> -0.0019363762 | D8: =('Price Data'!D8*(1+'Stock Dividend'!D8+'Right Share Ratio'!D8)*Split!D8-'Price Data'!D7-'Right Share Ratio'!D8*'Right Share Offer Price'!D8*Split!D8)/'Price Data'!D7 -> -0.0065359477 | E8: =('Price Data'!E8*(1+'Stock Dividend'!E8+'Right Share Ratio'!E8)*Split!E8-'Price Data'!E7-'Right Share Ratio'!E8*'Right Share Offer Price'!E8*Split!E8)/'Price Data'!E7 -> 0.015505985 | F8: =('Price Data'!F8*(1+'Stock Dividend'!F8+'Right Share Ratio'!F8)*Split!F8-'Price Data'!F7-'Right Share Ratio'!F8*'Right Share Offer Price'!F8*Split!F8)/'Price Data'!F7 -> -0.00385219 | G8: =('Price Data'!G8*(1+'Stock Dividend'!G8+'Right Share Ratio'!G8)*Split!G8-'Price Data'!G7-'Right Share Ratio'!G8*'Right Share Offer Price'!G8*Split!G8)/'Price Data'!G7 -> -0.028649386 | H8: =('Price Data'!H8*(1+'Stock Dividend'!H8+'Right Share Ratio'!H8)*Split!H8-'Price Data'!H7-'Right Share Ratio'!H8*'Right Share Offer Price'!H8*Split!H8)/'Price Data'!H7 -> -0.054014599 | I8: =('Price Data'!I8*(1+'Stock Dividend'!I8+'Right Share Ratio'!I8)*Split!I8-'Price Data'!I7-'Right Share Ratio'!I8*'Right Share Offer Price'!I8*Split!I8)/'Price Data'!I7 -> 0.15155483 | J8: =('Price Data'!J8*(1+'Stock Dividend'!J8+'Right Share Ratio'!J8)*Split!J8-'Price Data'!J7-'Right Share Ratio'!J8*'Right Share Offer Price'!J8*Split!J8)/'Price Data'!J7 -> -0.071428571 | ... V8: =('Price Data'!V8*(1+'Stock Dividend'!V8+'Right Share Ratio'!V8)*Split!V8-'Price Data'!V7-'Right Share Ratio'!V8*'Right Share Offer Price'!V8*Split!V8)/'Price Data'!V7 -> -0.019286967
B9: February | C9: =('Price Data'!C9*(1+'Stock Dividend'!C9+'Right Share Ratio'!C9)*Split!C9-'Price Data'!C8-'Right Share Ratio'!C9*'Right Share Offer Price'!C9*Split!C9)/'Price Data'!C8 -> -0.021618625 | D9: =('Price Data'!D9*(1+'Stock Dividend'!D9+'Right Share Ratio'!D9)*Split!D9-'Price Data'!D8-'Right Share Ratio'!D9*'Right Share Offer Price'!D9*Split!D9)/'Price Data'!D8 -> -0.013157895 | E9: =('Price Data'!E9*(1+'Stock Dividend'!E9+'Right Share Ratio'!E9)*Split!E9-'Price Data'!E8-'Right Share Ratio'!E9*'Right Share Offer Price'!E9*Split!E9)/'Price Data'!E8 -> -0.071256362 | F9: =('Price Data'!F9*(1+'Stock Dividend'!F9+'Right Share Ratio'!F9)*Split!F9-'Price Data'!F8-'Right Share Ratio'!F9*'Right Share Offer Price'!F9*Split!F9)/'Price Data'!F8 -> -0.045545689 | G9: =('Price Data'!G9*(1+'Stock Dividend'!G9+'Right Share Ratio'!G9)*Split!G9-'Price Data'!G8-'Right Share Ratio'!G9*'Right Share Offer Price'!G9*Split!G9)/'Price Data'!G8 -> -0.058988764 | H9: =('Price Data'!H9*(1+'Stock Dividend'!H9+'Right Share Ratio'!H9)*Split!H9-'Price Data'!H8-'Right Share Ratio'!H9*'Right Share Offer Price'!H9*Split!H9)/'Price Data'!H8 -> -0.12191358 | I9: =('Price Data'!I9*(1+'Stock Dividend'!I9+'Right Share Ratio'!I9)*Split!I9-'Price Data'!I8-'Right Share Ratio'!I9*'Right Share Offer Price'!I9*Split!I9)/'Price Data'!I8 -> -0.054292211 | J9: =('Price Data'!J9*(1+'Stock Dividend'!J9+'Right Share Ratio'!J9)*Split!J9-'Price Data'!J8-'Right Share Ratio'!J9*'Right Share Offer Price'!J9*Split!J9)/'Price Data'!J8 -> 0.023504274 | ... V9: =('Price Data'!V9*(1+'Stock Dividend'!V9+'Right Share Ratio'!V9)*Split!V9-'Price Data'!V8-'Right Share Ratio'!V9*'Right Share Offer Price'!V9*Split!V9)/'Price Data'!V8 -> 0.0023837902
B10: March | C10: =('Price Data'!C10*(1+'Stock Dividend'!C10+'Right Share Ratio'!C10)*Split!C10-'Price Data'!C9-'Right Share Ratio'!C10*'Right Share Offer Price'!C10*Split!C10)/'Price Data'!C9 -> -0.079603399 | D10: =('Price Data'!D10*(1+'Stock Dividend'!D10+'Right Share Ratio'!D10)*Split!D10-'Price Data'!D9-'Right Share Ratio'!D10*'Right Share Offer Price'!D10*Split!D10)/'Price Data'!D9 -> 0.026666667 | E10: =('Price Data'!E10*(1+'Stock Dividend'!E10+'Right Share Ratio'!E10)*Split!E10-'Price Data'!E9-'Right Share Ratio'!E10*'Right Share Offer Price'!E10*Split!E10)/'Price Data'!E9 -> 0.13441015 | F10: =('Price Data'!F10*(1+'Stock Dividend'!F10+'Right Share Ratio'!F10)*Split!F10-'Price Data'!F9-'Right Share Ratio'!F10*'Right Share Offer Price'!F10*Split!F10)/'Price Data'!F9 -> 0.082833133 | G10: =('Price Data'!G10*(1+'Stock Dividend'!G10+'Right Share Ratio'!G10)*Split!G10-'Price Data'!G9-'Right Share Ratio'!G10*'Right Share Offer Price'!G10*Split!G10)/'Price Data'!G9 -> -0.08358209 | H10: =('Price Data'!H10*(1+'Stock Dividend'!H10+'Right Share Ratio'!H10)*Split!H10-'Price Data'!H9-'Right Share Ratio'!H10*'Right Share Offer Price'!H10*Split!H10)/'Price Data'!H9 -> -0.029876977 | I10: =('Price Data'!I10*(1+'Stock Dividend'!I10+'Right Share Ratio'!I10)*Split!I10-'Price Data'!I9-'Right Share Ratio'!I10*'Right Share Offer Price'!I10*Split!I10)/'Price Data'!I9 -> 0.13946498 | J10: =('Price Data'!J10*(1+'Stock Dividend'!J10+'Right Share Ratio'!J10)*Split!J10-'Price Data'!J9-'Right Share Ratio'!J10*'Right Share Offer Price'!J10*Split!J10)/'Price Data'!J9 -> -0.048016701 | ... V10: =('Price Data'!V10*(1+'Stock Dividend'!V10+'Right Share Ratio'!V10)*Split!V10-'Price Data'!V9-'Right Share Ratio'!V10*'Right Share Offer Price'!V10*Split!V10)/'Price Data'!V9 -> -0.029726516
B11: April | C11: =('Price Data'!C11*(1+'Stock Dividend'!C11+'Right Share Ratio'!C11)*Split!C11-'Price Data'!C10-'Right Share Ratio'!C11*'Right Share Offer Price'!C11*Split!C11)/'Price Data'!C10 -> 0.069375192 | D11: =('Price Data'!D11*(1+'Stock Dividend'!D11+'Right Share Ratio'!D11)*Split!D11-'Price Data'!D10-'Right Share Ratio'!D11*'Right Share Offer Price'!D11*Split!D11)/'Price Data'!D10 -> 0.012987013 | E11: =('Price Data'!E11*(1+'Stock Dividend'!E11+'Right Share Ratio'!E11)*Split!E11-'Price Data'!E10-'Right Share Ratio'!E11*'Right Share Offer Price'!E11*Split!E11)/'Price Data'!E10 -> 0.37782863 | F11: =('Price Data'!F11*(1+'Stock Dividend'!F11+'Right Share Ratio'!F11)*Split!F11-'Price Data'!F10-'Right Share Ratio'!F11*'Right Share Offer Price'!F11*Split!F11)/'Price Data'!F10 -> 0.012195122 | G11: =('Price Data'!G11*(1+'Stock Dividend'!G11+'Right Share Ratio'!G11)*Split!G11-'Price Data'!G10-'Right Share Ratio'!G11*'Right Share Offer Price'!G11*Split!G11)/'Price Data'!G10 -> -0.070032573 | H11: =('Price Data'!H11*(1+'Stock Dividend'!H11+'Right Share Ratio'!H11)*Split!H11-'Price Data'!H10-'Right Share Ratio'!H11*'Right Share Offer Price'!H11*Split!H11)/'Price Data'!H10 -> 0.041666667 | I11: =('Price Data'!I11*(1+'Stock Dividend'!I11+'Right Share Ratio'!I11)*Split!I11-'Price Data'!I10-'Right Share Ratio'!I11*'Right Share Offer Price'!I11*Split!I11)/'Price Data'!I10 -> 0.011870219 | J11: =('Price Data'!J11*(1+'Stock Dividend'!J11+'Right Share Ratio'!J11)*Split!J11-'Price Data'!J10-'Right Share Ratio'!J11*'Right Share Offer Price'!J11*Split!J11)/'Price Data'!J10 -> -0.083333333 | ... V11: =('Price Data'!V11*(1+'Stock Dividend'!V11+'Right Share Ratio'!V11)*Split!V11-'Price Data'!V10-'Right Share Ratio'!V11*'Right Share Offer Price'!V11*Split!V11)/'Price Data'!V10 -> 0.026960784
